Workbook

Sheet 📖 Como Usar
A1: Como usar esta planilha
A3: O que é
A4: Checklist de correção dos anúncios do Mercado Livre da Essência do Brasil e Ponte Vecchio Joias, baseado em auditoria automática de 6.549 anúncios. Esta planilha é só um checklist de acompanhamento - a correção de verdade é feita direto no painel do Mercado Livre.
A6: Abas de categoria (Perfumes, Óleos Essenciais, Colares, Pingentes, Joias e Acessórios, Difusores e Aromatizadores, Cuidados Pessoais)
A7: Cada linha é um anúncio com pelo menos um problema encontrado. "Cada um pega o que der": qualquer pessoa da equipe pode abrir a aba, escolher uma linha, clicar no link para abrir o anúncio no Mercado Livre, corrigir lá, e depois atualizar o Status aqui.
A9: Coluna Status
A10: "Não verificado" (ainda não olhado) → "Em andamento" (alguém já está corrigindo) → "Corrigido" (já ajustado no Mercado Livre) → "Não se aplica" (revisado e não precisa mexer). As cores mudam sozinhas.
A12: Coluna Gravidade
A13: 🔴 Crítico = risco de bloqueio/penalização da conta ou de venda errada. 🟠 Alto = pode levar o cliente a comprar errado. 🟡 Médio = atributo técnico incompleto, sem risco imediato. 🔵 Baixo = padronização/cosmético.
A15: Colunas Responsável / Data / Observações
A16: Preencha com seu nome, a data que corrigiu, e qualquer observação relevante (ex: "já estava certo, falso positivo").
A18: 🗑️ Descontinuar
... A37: Um código opcional de Apps Script foi entregue separadamente (menu personalizado, trava de colunas, carimbo de data automático). Veja as instruções de instalação no arquivo entregue junto.

Sheet 📊 Painel Geral
A1: Painel de Correção de Anúncios — Mercado Livre
A2: Essência do Brasil · Ponte Vecchio Joias
A4: Total de Anúncios Auditados | C4: Concluídos | E4: Em Andamento | G4: Críticos em Aberto | I4: % Concluído
A5: =COUNTIF('🧴 Perfumes'!$C$2:$C$3139,"<>")+COUNTIF('💧 Óleos Essenciais'!$C$2:$C$1533,"<>")+COUNTIF('📿 Colares'!$C$2:$C$425,"<>")+COUNTIF('🔶 Pingentes'!$C$2:$C$501,"<>")+COUNTIF('💍 Joias e Acessórios'!$C$2:$C$36,"<>")+COUNTIF('🌬️ Difusores e Aromatizadores'!$C$2:$C$45,"<>")+COUNTIF('🧖 Cuidados Pessoais'!$C$2:$C$56,"<>") -> 5728 | C5: =COUNTIF('🧴 Perfumes'!$A$2:$A$3139,"Corrigido")+COUNTIF('💧 Óleos Essenciais'!$A$2:$A$1533,"Corrigido")+COUNTIF('📿 Colares'!$A$2:$A$425,"Corrigido")+COUNTIF('🔶 Pingentes'!$A$2:$A$501,"Corrigido")+COUNTIF('💍 Joias e Acessórios'!$A$2:$A$36,"Corrigido")+COUNTIF('🌬️ Difusores e Aromatizadores'!$A$2:$A$45,"Corrigido")+COUNTIF('🧖 Cuidados Pessoais'!$A$2:$A$56,"Corrigido") -> 0 | E5: =COUNTIF('🧴 Perfumes'!$A$2:$A$3139,"Em andamento")+COUNTIF('💧 Óleos Essenciais'!$A$2:$A$1533,"Em andamento")+COUNTIF('📿 Colares'!$A$2:$A$425,"Em andamento")+COUNTIF('🔶 Pingentes'!$A$2:$A$501,"Em andamento")+COUNTIF('💍 Joias e Acessórios'!$A$2:$A$36,"Em andamento")+COUNTIF('🌬️ Difusores e Aromatizadores'!$A$2:$A$45,"Em andamento")+COUNTIF('🧖 Cuidados Pessoais'!$A$2:$A$56,"Em andamento") -> 0 | G5: =COUNTIFS('🧴 Perfumes'!$B$2:$B$3139,"Crítico",'🧴 Perfumes'!$A$2:$A$3139,"<>Corrigido")+COUNTIFS('💧 Óleos Essenciais'!$B$2:$B$1533,"Crítico",'💧 Óleos Essenciais'!$A$2:$A$1533,"<>Corrigido")+COUNTIFS('📿 Colares'!$B$2:$B$425,"Crítico",'📿 Colares'!$A$2:$A$425,"<>Corrigido")+COUNTIFS('🔶 Pingentes'!$B$2:$B$501,"Crítico",'🔶 Pingentes'!$A$2:$A$501,"<>Corrigido")+COUNTIFS('💍 Joias e Acessórios'!$B$2:$B$36,"Crítico",'💍 Joias e Acessórios'!$A$2:$A$36,"<>Corrigido")+COUNTIFS('🌬️ Difusores e Aromatizadores'!$B$2:$B$45,"Crítico",'🌬️ Difusores e Aromatizadores'!$A$2:$A$45,"<>Corrigido")+COUNTIFS('🧖 Cuidados Pessoais'!$B$2:$B$56,"Crítico",'🧖 Cuidados Pessoais'!$A$2:$A$56,"<>Corrigido") -> 630 | I5: =COUNTIF('🧴 Perfumes'!$A$2:$A$3139,"Corrigido")+COUNTIF('💧 Óleos Essenciais'!$A$2:$A$1533,"Corrigido")+COUNTIF('📿 Colares'!$A$2:$A$425,"Corrigido")+COUNTIF('🔶 Pingentes'!$A$2:$A$501,"Corrigido")+COUNTIF('💍 Joias e Acessórios'!$A$2:$A$36,"Corrigido")+COUNTIF('🌬️ Difusores e Aromatizadores'!$A$2:$A$45,"Corrigido")+COUNTIF('🧖 Cuidados Pessoais'!$A$2:$A$56,"Corrigido")/COUNTIF('🧴 Perfumes'!$C$2:$C$3139,"<>")+COUNTIF('💧 Óleos Essenciais'!$C$2:$C$1533,"<>")+COUNTIF('📿 Colares'!$C$2:$C$425,"<>")+COUNTIF('🔶 Pingentes'!$C$2:$C$501,"<>")+COUNTIF('💍 Joias e Acessórios'!$C$2:$C$36,"<>")+COUNTIF('🌬️ Difusores e Aromatizadores'!$C$2:$C$45,"<>")+COUNTIF('🧖 Cuidados Pessoais'!$C$2:$C$56,"<>") -> 2590
A9: Progresso por Gravidade
A10: Gravidade | B10: Total | C10: Concluído | D10: Em Andamento | E10: Pendente | F10: % Concluído
A11: Crítico | B11: =COUNTIFS('🧴 Perfumes'!$B$2:$B$3139,"Crítico")+COUNTIFS('💧 Óleos Essenciais'!$B$2:$B$1533,"Crítico")+COUNTIFS('📿 Colares'!$B$2:$B$425,"Crítico")+COUNTIFS('🔶 Pingentes'!$B$2:$B$501,"Crítico")+COUNTIFS('💍 Joias e Acessórios'!$B$2:$B$36,"Crítico")+COUNTIFS('🌬️ Difusores e Aromatizadores'!$B$2:$B$45,"Crítico")+COUNTIFS('🧖 Cuidados Pessoais'!$B$2:$B$56,"Crítico") -> 630 | C11: =COUNTIFS('🧴 Perfumes'!$B$2:$B$3139,"Crítico",'🧴 Perfumes'!$A$2:$A$3139,"Corrigido")+COUNTIFS('💧 Óleos Essenciais'!$B$2:$B$1533,"Crítico",'💧 Óleos Essenciais'!$A$2:$A$1533,"Corrigido")+COUNTIFS('📿 Colares'!$B$2:$B$425,"Crítico",'📿 Colares'!$A$2:$A$425,"Corrigido")+COUNTIFS('🔶 Pingentes'!$B$2:$B$501,"Crítico",'🔶 Pingentes'!$A$2:$A$501,"Corrigido")+COUNTIFS('💍 Joias e Acessórios'!$B$2:$B$36,"Crítico",'💍 Joias e Acessórios'!$A$2:$A$36,"Corrigido")+COUNTIFS('🌬️ Difusores e Aromatizadores'!$B$2:$B$45,"Crítico",'🌬️ Difusores e Aromatizadores'!$A$2:$A$45,"Corrigido")+COUNTIFS('🧖 Cuidados Pessoais'!$B$2:$B$56,"Crítico",'🧖 Cuidados Pessoais'!$A$2:$A$56,"Corrigido") -> 0 | D11: =COUNTIFS('🧴 Perfumes'!$B$2:$B$3139,"Crítico",'🧴 Perfumes'!$A$2:$A$3139,"Em andamento")+COUNTIFS('💧 Óleos Essenciais'!$B$2:$B$1533,"Crítico",'💧 Óleos Essenciais'!$A$2:$A$1533,"Em andamento")+COUNTIFS('📿 Colares'!$B$2:$B$425,"Crítico",'📿 Colares'!$A$2:$A$425,"Em andamento")+COUNTIFS('🔶 Pingentes'!$B$2:$B$501,"Crítico",'🔶 Pingentes'!$A$2:$A$501,"Em andamento")+COUNTIFS('💍 Joias e Acessórios'!$B$2:$B$36,"Crítico",'💍 Joias e Acessórios'!$A$2:$A$36,"Em andamento")+COUNTIFS('🌬️ Difusores e Aromatizadores'!$B$2:$B$45,"Crítico",'🌬️ Difusores e Aromatizadores'!$A$2:$A$45,"Em andamento")+COUNTIFS('🧖 Cuidados Pessoais'!$B$2:$B$56,"Crítico",'🧖 Cuidados Pessoais'!$A$2:$A$56,"Em andamento") -> 0 | E11: =B11-C11-D11 -> 630 | F11: =IF(B11=0,0,C11/B11) -> 0
A12: Alto | B12: =COUNTIFS('🧴 Perfumes'!$B$2:$B$3139,"Alto")+COUNTIFS('💧 Óleos Essenciais'!$B$2:$B$1533,"Alto")+COUNTIFS('📿 Colares'!$B$2:$B$425,"Alto")+COUNTIFS('🔶 Pingentes'!$B$2:$B$501,"Alto")+COUNTIFS('💍 Joias e Acessórios'!$B$2:$B$36,"Alto")+COUNTIFS('🌬️ Difusores e Aromatizadores'!$B$2:$B$45,"Alto")+COUNTIFS('🧖 Cuidados Pessoais'!$B$2:$B$56,"Alto") -> 2781 | C12: =COUNTIFS('🧴 Perfumes'!$B$2:$B$3139,"Alto",'🧴 Perfumes'!$A$2:$A$3139,"Corrigido")+COUNTIFS('💧 Óleos Essenciais'!$B$2:$B$1533,"Alto",'💧 Óleos Essenciais'!$A$2:$A$1533,"Corrigido")+COUNTIFS('📿 Colares'!$B$2:$B$425,"Alto",'📿 Colares'!$A$2:$A$425,"Corrigido")+COUNTIFS('🔶 Pingentes'!$B$2:$B$501,"Alto",'🔶 Pingentes'!$A$2:$A$501,"Corrigido")+COUNTIFS('💍 Joias e Acessórios'!$B$2:$B$36,"Alto",'💍 Joias e Acessórios'!$A$2:$A$36,"Corrigido")+COUNTIFS('🌬️ Difusores e Aromatizadores'!$B$2:$B$45,"Alto",'🌬️ Difusores e Aromatizadores'!$A$2:$A$45,"Corrigido")+COUNTIFS('🧖 Cuidados Pessoais'!$B$2:$B$56,"Alto",'🧖 Cuidados Pessoais'!$A$2:$A$56,"Corrigido") -> 0 | D12: =COUNTIFS('🧴 Perfumes'!$B$2:$B$3139,"Alto",'🧴 Perfumes'!$A$2:$A$3139,"Em andamento")+COUNTIFS('💧 Óleos Essenciais'!$B$2:$B$1533,"Alto",'💧 Óleos Essenciais'!$A$2:$A$1533,"Em andamento")+COUNTIFS('📿 Colares'!$B$2:$B$425,"Alto",'📿 Colares'!$A$2:$A$425,"Em andamento")+COUNTIFS('🔶 Pingentes'!$B$2:$B$501,"Alto",'🔶 Pingentes'!$A$2:$A$501,"Em andamento")+COUNTIFS('💍 Joias e Acessórios'!$B$2:$B$36,"Alto",'💍 Joias e Acessórios'!$A$2:$A$36,"Em andamento")+COUNTIFS('🌬️ Difusores e Aromatizadores'!$B$2:$B$45,"Alto",'🌬️ Difusores e Aromatizadores'!$A$2:$A$45,"Em andamento")+COUNTIFS('🧖 Cuidados Pessoais'!$B$2:$B$56,"Alto",'🧖 Cuidados Pessoais'!$A$2:$A$56,"Em andamento") -> 0 | E12: =B12-C12-D12 -> 2781 | F12: =IF(B12=0,0,C12/B12) -> 0
A13: Médio | B13: =COUNTIFS('🧴 Perfumes'!$B$2:$B$3139,"Médio")+COUNTIFS('💧 Óleos Essenciais'!$B$2:$B$1533,"Médio")+COUNTIFS('📿 Colares'!$B$2:$B$425,"Médio")+COUNTIFS('🔶 Pingentes'!$B$2:$B$501,"Médio")+COUNTIFS('💍 Joias e Acessórios'!$B$2:$B$36,"Médio")+COUNTIFS('🌬️ Difusores e Aromatizadores'!$B$2:$B$45,"Médio")+COUNTIFS('🧖 Cuidados Pessoais'!$B$2:$B$56,"Médio") -> 2317 | C13: =COUNTIFS('🧴 Perfumes'!$B$2:$B$3139,"Médio",'🧴 Perfumes'!$A$2:$A$3139,"Corrigido")+COUNTIFS('💧 Óleos Essenciais'!$B$2:$B$1533,"Médio",'💧 Óleos Essenciais'!$A$2:$A$1533,"Corrigido")+COUNTIFS('📿 Colares'!$B$2:$B$425,"Médio",'📿 Colares'!$A$2:$A$425,"Corrigido")+COUNTIFS('🔶 Pingentes'!$B$2:$B$501,"Médio",'🔶 Pingentes'!$A$2:$A$501,"Corrigido")+COUNTIFS('💍 Joias e Acessórios'!$B$2:$B$36,"Médio",'💍 Joias e Acessórios'!$A$2:$A$36,"Corrigido")+COUNTIFS('🌬️ Difusores e Aromatizadores'!$B$2:$B$45,"Médio",'🌬️ Difusores e Aromatizadores'!$A$2:$A$45,"Corrigido")+COUNTIFS('🧖 Cuidados Pessoais'!$B$2:$B$56,"Médio",'🧖 Cuidados Pessoais'!$A$2:$A$56,"Corrigido") -> 0 | D13: =COUNTIFS('🧴 Perfumes'!$B$2:$B$3139,"Médio",'🧴 Perfumes'!$A$2:$A$3139,"Em andamento")+COUNTIFS('💧 Óleos Essenciais'!$B$2:$B$1533,"Médio",'💧 Óleos Essenciais'!$A$2:$A$1533,"Em andamento")+COUNTIFS('📿 Colares'!$B$2:$B$425,"Médio",'📿 Colares'!$A$2:$A$425,"Em andamento")+COUNTIFS('🔶 Pingentes'!$B$2:$B$501,"Médio",'🔶 Pingentes'!$A$2:$A$501,"Em andamento")+COUNTIFS('💍 Joias e Acessórios'!$B$2:$B$36,"Médio",'💍 Joias e Acessórios'!$A$2:$A$36,"Em andamento")+COUNTIFS('🌬️ Difusores e Aromatizadores'!$B$2:$B$45,"Médio",'🌬️ Difusores e Aromatizadores'!$A$2:$A$45,"Em andamento")+COUNTIFS('🧖 Cuidados Pessoais'!$B$2:$B$56,"Médio",'🧖 Cuidados Pessoais'!$A$2:$A$56,"Em andamento") -> 0 | E13: =B13-C13-D13 -> 2317 | F13: =IF(B13=0,0,C13/B13) -> 0
A14: Baixo | B14: =COUNTIFS('🧴 Perfumes'!$B$2:$B$3139,"Baixo")+COUNTIFS('💧 Óleos Essenciais'!$B$2:$B$1533,"Baixo")+COUNTIFS('📿 Colares'!$B$2:$B$425,"Baixo")+COUNTIFS('🔶 Pingentes'!$B$2:$B$501,"Baixo")+COUNTIFS('💍 Joias e Acessórios'!$B$2:$B$36,"Baixo")+COUNTIFS('🌬️ Difusores e Aromatizadores'!$B$2:$B$45,"Baixo")+COUNTIFS('🧖 Cuidados Pessoais'!$B$2:$B$56,"Baixo") -> 0 | C14: =COUNTIFS('🧴 Perfumes'!$B$2:$B$3139,"Baixo",'🧴 Perfumes'!$A$2:$A$3139,"Corrigido")+COUNTIFS('💧 Óleos Essenciais'!$B$2:$B$1533,"Baixo",'💧 Óleos Essenciais'!$A$2:$A$1533,"Corrigido")+COUNTIFS('📿 Colares'!$B$2:$B$425,"Baixo",'📿 Colares'!$A$2:$A$425,"Corrigido")+COUNTIFS('🔶 Pingentes'!$B$2:$B$501,"Baixo",'🔶 Pingentes'!$A$2:$A$501,"Corrigido")+COUNTIFS('💍 Joias e Acessórios'!$B$2:$B$36,"Baixo",'💍 Joias e Acessórios'!$A$2:$A$36,"Corrigido")+COUNTIFS('🌬️ Difusores e Aromatizadores'!$B$2:$B$45,"Baixo",'🌬️ Difusores e Aromatizadores'!$A$2:$A$45,"Corrigido")+COUNTIFS('🧖 Cuidados Pessoais'!$B$2:$B$56,"Baixo",'🧖 Cuidados Pessoais'!$A$2:$A$56,"Corrigido") -> 0 | D14: =COUNTIFS('🧴 Perfumes'!$B$2:$B$3139,"Baixo",'🧴 Perfumes'!$A$2:$A$3139,"Em andamento")+COUNTIFS('💧 Óleos Essenciais'!$B$2:$B$1533,"Baixo",'💧 Óleos Essenciais'!$A$2:$A$1533,"Em andamento")+COUNTIFS('📿 Colares'!$B$2:$B$425,"Baixo",'📿 Colares'!$A$2:$A$425,"Em andamento")+COUNTIFS('🔶 Pingentes'!$B$2:$B$501,"Baixo",'🔶 Pingentes'!$A$2:$A$501,"Em andamento")+COUNTIFS('💍 Joias e Acessórios'!$B$2:$B$36,"Baixo",'💍 Joias e Acessórios'!$A$2:$A$36,"Em andamento")+COUNTIFS('🌬️ Difusores e Aromatizadores'!$B$2:$B$45,"Baixo",'🌬️ Difusores e Aromatizadores'!$A$2:$A$45,"Em andamento")+COUNTIFS('🧖 Cuidados Pessoais'!$B$2:$B$56,"Baixo",'🧖 Cuidados Pessoais'!$A$2:$A$56,"Em andamento") -> 0 | E14: =B14-C14-D14 -> 0 | F14: =IF(B14=0,0,C14/B14) -> 0
A17: Progresso por Categoria
A18: Categoria | B18: Total | C18: Concluído | D18: Em Andamento | E18: Pendente | F18: % Concluído
A19: 🧴 Perfumes | B19: =COUNTIF('🧴 Perfumes'!$C$2:$C$3139,"<>") -> 3138 | C19: =COUNTIF('🧴 Perfumes'!$A$2:$A$3139,"Corrigido") -> 0 | D19: =COUNTIF('🧴 Perfumes'!$A$2:$A$3139,"Em andamento") -> 0 | E19: =B19-C19-D19 -> 3138 | F19: =IF(B19=0,0,C19/B19) -> 0
A20: 💧 Óleos Essenciais | B20: =COUNTIF('💧 Óleos Essenciais'!$C$2:$C$1533,"<>") -> 1532 | C20: =COUNTIF('💧 Óleos Essenciais'!$A$2:$A$1533,"Corrigido") -> 0 | D20: =COUNTIF('💧 Óleos Essenciais'!$A$2:$A$1533,"Em andamento") -> 0 | E20: =B20-C20-D20 -> 1532 | F20: =IF(B20=0,0,C20/B20) -> 0
A21: 📿 Colares | B21: =COUNTIF('📿 Colares'!$C$2:$C$425,"<>") -> 424 | C21: =COUNTIF('📿 Colares'!$A$2:$A$425,"Corrigido") -> 0 | D21: =COUNTIF('📿 Colares'!$A$2:$A$425,"Em andamento") -> 0 | E21: =B21-C21-D21 -> 424 | F21: =IF(B21=0,0,C21/B21) -> 0
A22: 🔶 Pingentes | B22: =COUNTIF('🔶 Pingentes'!$C$2:$C$501,"<>") -> 500 | C22: =COUNTIF('🔶 Pingentes'!$A$2:$A$501,"Corrigido") -> 0 | D22: =COUNTIF('🔶 Pingentes'!$A$2:$A$501,"Em andamento") -> 0 | E22: =B22-C22-D22 -> 500 | F22: =IF(B22=0,0,C22/B22) -> 0
A23: 💍 Joias e Acessórios | B23: =COUNTIF('💍 Joias e Acessórios'!$C$2:$C$36,"<>") -> 35 | C23: =COUNTIF('💍 Joias e Acessórios'!$A$2:$A$36,"Corrigido") -> 0 | D23: =COUNTIF('💍 Joias e Acessórios'!$A$2:$A$36,"Em andamento") -> 0 | E23: =B23-C23-D23 -> 35 | F23: =IF(B23=0,0,C23/B23) -> 0
A24: 🌬️ Difusores e Aromatizadores | B24: =COUNTIF('🌬️ Difusores e Aromatizadores'!$C$2:$C$45,"<>") -> 44 | C24: =COUNTIF('🌬️ Difusores e Aromatizadores'!$A$2:$A$45,"Corrigido") -> 0 | D24: =COUNTIF('🌬️ Difusores e Aromatizadores'!$A$2:$A$45,"Em andamento") -> 0 | E24: =B24-C24-D24 -> 44 | F24: =IF(B24=0,0,C24/B24) -> 0
A25: 🧖 Cuidados Pessoais | B25: =COUNTIF('🧖 Cuidados Pessoais'!$C$2:$C$56,"<>") -> 55 | C25: =COUNTIF('🧖 Cuidados Pessoais'!$A$2:$A$56,"Corrigido") -> 0 | D25: =COUNTIF('🧖 Cuidados Pessoais'!$A$2:$A$56,"Em andamento") -> 0 | E25: =B25-C25-D25 -> 55 | F25: =IF(B25=0,0,C25/B25) -> 0
A28: Distribuição por Status
A29: Não verificado | B29: =COUNTIF('🧴 Perfumes'!$A$2:$A$3139,"Não verificado")+COUNTIF('💧 Óleos Essenciais'!$A$2:$A$1533,"Não verificado")+COUNTIF('📿 Colares'!$A$2:$A$425,"Não verificado")+COUNTIF('🔶 Pingentes'!$A$2:$A$501,"Não verificado")+COUNTIF('💍 Joias e Acessórios'!$A$2:$A$36,"Não verificado")+COUNTIF('🌬️ Difusores e Aromatizadores'!$A$2:$A$45,"Não verificado")+COUNTIF('🧖 Cuidados Pessoais'!$A$2:$A$56,"Não verificado") -> 5728
A30: Em andamento | B30: =COUNTIF('🧴 Perfumes'!$A$2:$A$3139,"Em andamento")+COUNTIF('💧 Óleos Essenciais'!$A$2:$A$1533,"Em andamento")+COUNTIF('📿 Colares'!$A$2:$A$425,"Em andamento")+COUNTIF('🔶 Pingentes'!$A$2:$A$501,"Em andamento")+COUNTIF('💍 Joias e Acessórios'!$A$2:$A$36,"Em andamento")+COUNTIF('🌬️ Difusores e Aromatizadores'!$A$2:$A$45,"Em andamento")+COUNTIF('🧖 Cuidados Pessoais'!$A$2:$A$56,"Em andamento") -> 0
A31: Corrigido | B31: =COUNTIF('🧴 Perfumes'!$A$2:$A$3139,"Corrigido")+COUNTIF('💧 Óleos Essenciais'!$A$2:$A$1533,"Corrigido")+COUNTIF('📿 Colares'!$A$2:$A$425,"Corrigido")+COUNTIF('🔶 Pingentes'!$A$2:$A$501,"Corrigido")+COUNTIF('💍 Joias e Acessórios'!$A$2:$A$36,"Corrigido")+COUNTIF('🌬️ Difusores e Aromatizadores'!$A$2:$A$45,"Corrigido")+COUNTIF('🧖 Cuidados Pessoais'!$A$2:$A$56,"Corrigido") -> 0
A32: Não se aplica | B32: =COUNTIF('🧴 Perfumes'!$A$2:$A$3139,"Não se aplica")+COUNTIF('💧 Óleos Essenciais'!$A$2:$A$1533,"Não se aplica")+COUNTIF('📿 Colares'!$A$2:$A$425,"Não se aplica")+COUNTIF('🔶 Pingentes'!$A$2:$A$501,"Não se aplica")+COUNTIF('💍 Joias e Acessórios'!$A$2:$A$36,"Não se aplica")+COUNTIF('🌬️ Difusores e Aromatizadores'!$A$2:$A$45,"Não se aplica")+COUNTIF('🧖 Cuidados Pessoais'!$A$2:$A$56,"Não se aplica") -> 0

Sheet 🧴 Perfumes
A1: Status | B1: Gravidade | C1: Código do Anúncio | D1: Link | E1: Título Atual | F1: Situação no ML | G1: Problema(s) Encontrado(s) | H1: Detalhes / Sugestão de Correção | I1: Responsável | J1: Data | K1: Observações
A2: Não verificado | B2: Crítico | C2: MLB1786382784 | D2: =HYPERLINK("https://www.mercadolivre.com.br/anuncios?page=1&sort=DEFAULT&search="&C2,"Abrir anúncio ↗") -> Abrir anúncio ↗ | E2: Perfume Almíscar Selvagem 100ml - Masculino | F2: Ativo | G2: Descrição repetida em outros anúncios com título diferente (verificar se é boilerplate ou erro); Documento de Notificação/Comunicação prévia na Anvisa não preenchido; Possível menção a marca concorrente no título/descrição | H2: Possível menção a marca concorrente no título/descrição: Possível menção a marca concorrente "chanel" | Descrição repetida em outros anúncios com título diferente (verificar se é boilerplate ou erro): Mesma descrição usada em 2 anúncios com títulos diferentes | Documento de Notificação/Comunicação prévia na Anvisa não preenchido: Número de Notificação/Comunicação prévia na Anvisa não preenchido
A3: Não verificado | B3: Crítico | C3: MLB1926329694 | D3: =HYPERLINK("https://www.mercadolivre.com.br/anuncios?page=1&sort=DEFAULT&search="&C3,"Abrir anúncio ↗") -> Abrir anúncio ↗ | E3: Perfume Almíscar Selvagem 100ml Masculino + Mni Perfume 10ml | F3: Ativo | G3: Descrição repetida em outros anúncios com título diferente (verificar se é boilerplate ou erro); Documento de Notificação/Comunicação prévia na Anvisa não preenchido; Possível menção a marca concorrente no título/descrição | H3: Possível menção a marca concorrente no título/descrição: Possível menção a marca concorrente "chanel" | Descrição repetida em outros anúncios com título diferente (verificar se é boilerplate ou erro): Mesma descrição usada em 2 anúncios com títulos diferentes | Documento de Notificação/Comunicação prévia na Anvisa não preenchido: Número de Notificação/Comunicação prévia na Anvisa não preenchido
A4: Não verificado | B4: Crítico | C4: MLB2199406677 | D4: =HYPERLINK("https://www.mercadolivre.com.br/anuncios?page=1&sort=DEFAULT&search="&C4,"Abrir anúncio ↗") -> Abrir anúncio ↗ | E4: Perfume Almíscar Selvagem 100ml + Perfume 30ml - Ed Especial | F4: Ativo | G4: Documento de Notificação/Comunicação prévia na Anvisa não preenchido; Possível menção a marca concorrente no título/descrição | H4: Possível menção a marca concorrente no título/descrição: Possível menção a marca concorrente "chanel" | Documento de Notificação/Comunicação prévia na Anvisa não preenchido: Número de Notificação/Comunicação prévia na Anvisa não preenchido
A5: Não verificado | B5: Crítico | C5: MLB3919357185 | D5: =HYPERLINK("https://www.mercadolivre.com.br/anuncios?page=1&sort=DEFAULT&search="&C5,"Abrir anúncio ↗") -> Abrir anúncio ↗ | E5: Perfume Feminino Essência Do Brasil Dama Da Noite & Baunilha 100ml | F5: Ativo | G5: Anúncio sem descrição; Anúncio sem preço definido; Documento de Notificação/Comunicação prévia na Anvisa não preenchido; País de origem diferente de "Brasil"; Título com mais de 60 caracteres | H5: Título com mais de 60 caracteres: Título com 66 caracteres (limite ML=60) | Anúncio sem descrição: Descrição vazia | Anúncio sem preço definido: Sem preço definido | País de origem diferente de "Brasil": País de origem = "(vazio)", deveria ser "Brasil" | Documento de Notificação/Comunicação prévia na Anvisa não preenchido: Número de Notificação/Comunicação prévia na Anvisa não preenchido
A6: Não verificado | B6: Crítico | C6: MLB4220216467 | D6: =HYPERLINK("https://www.mercadolivre.com.br/anuncios?page=1&sort=DEFAULT&search="&C6,"Abrir anúncio ↗") -> Abrir anúncio ↗ | E6: Perfume Essencial Natura Eau De Parfum Masculino 100 Ml | F6: Ativo | G6: Documento de Notificação/Comunicação prévia na Anvisa não preenchido; Gênero cadastrado diverge do gênero indicado no título; Marca cadastrada incorreta/inconsistente; Possível menção a marca concorrente no título/descrição | H6: Possível menção a marca concorrente no título/descrição: Possível menção a marca concorrente "natura" | Marca cadastrada incorreta/inconsistente: Marca "Natura" difere da marca própria esperada "Essência do Brasil" | Documento de Notificação/Comunicação prévia na Anvisa não preenchido: Número de Notificação/Comunicação prévia na Anvisa não preenchido | Gênero cadastrado diverge do gênero indicado no título: Título indica um gênero mas campo Gênero está "Feminino" - risco do cliente comprar errado
A7: Não verificado | B7: Crítico | C7: MLB5560866312 | D7: =HYPERLINK("https://www.mercadolivre.com.br/anuncios?page=1&sort=DEFAULT&search="&C7,"Abrir anúncio ↗") -> Abrir anúncio ↗ | E7: Perfume Sinergia 1 - Lavanda, Bergamota, Ylang-ylang 10ml | F7: Ativo | G7: Anúncio sem preço definido; Documento de Notificação/Comunicação prévia na Anvisa não preenchido | H7: Anúncio sem preço definido: Sem preço definido | Documento de Notificação/Comunicação prévia na Anvisa não preenchido: Número de Notificação/Comunicação prévia na Anvisa não preenchido
A8: Não verificado | B8: Alto | C8: MLB1349521824 | D8: =HYPERLINK("https://www.mercadolivre.com.br/anuncios?page=1&sort=DEFAULT&search="&C8,"Abrir anúncio ↗") -> Abrir anúncio ↗ | E8: Perfume Feminino Natural Pau Rosa 100ml | F8: Inativo | G8: Código universal do produto (GTIN) não preenchido (texto de exemplo do ML ainda lá); Descrição repetida em outros anúncios com título diferente (verificar se é boilerplate ou erro); Documento de Notificação/Comunicação prévia na Anvisa não preenchido | H8: Descrição repetida em outros anúncios com título diferente (verificar se é boilerplate ou erro): Mesma descrição usada em 27 anúncios com títulos diferentes | Código universal do produto (GTIN) não preenchido (texto de exemplo do ML ainda lá): Texto de exemplo do template não foi substituído pelo código real | Documento de Notificação/Comunicação prévia na Anvisa não preenchido: Número de Notificação/Comunicação prévia na Anvisa não preenchido
A9: Não verificado | B9: Alto | C9: MLB1349521825 | D9: =HYPERLINK("https://www.mercadolivre.com.br/anuncios?page=1&sort=DEFAULT&search="&C9,"Abrir anúncio ↗") -> Abrir anúncio ↗ | E9: Perfume Feminino Natural Flor Angélica 100ml | F9: Ativo | G9: Código universal do produto (GTIN) não preenchido (texto de exemplo do ML ainda lá); Documento de Notificação/Comunicação prévia na Anvisa não preenchido; Marca cadastrada incorreta/inconsistente; País de origem diferente de "Brasil" | H9: Marca cadastrada incorreta/inconsistente: Marca "Perfume" difere da marca própria esperada "Essência do Brasil" | Código universal do produto (GTIN) não preenchido (texto de exemplo do ML ainda lá): Texto de exemplo do template não foi substituído pelo código real | País de origem diferente de "Brasil": País de origem = "(vazio)", deveria ser "Brasil" | Documento de Notificação/Comunicação prévia na Anvisa não preenchido: Número de Notificação/Comunicação prévia na Anvisa não preenchido
A10: Não verificado | B10: Alto | C10: MLB1349521834 | D10: =HYPERLINK("https://www.mercadolivre.com.br/anuncios?page=1&sort=DEFAULT&search="&C10,"Abrir anúncio ↗") -> Abrir anúncio ↗ | E10: Perfume Feminino Natural De Gardênia 100ml | F10: Ativo | G10: Descrição repetida em outros anúncios com título diferente (verificar se é boilerplate ou erro); Documento de Notificação/Comunicação prévia na Anvisa não preenchido | H10: Descrição repetida em outros anúncios com título diferente (verificar se é boilerplate ou erro): Mesma descrição usada em 27 anúncios com títulos diferentes | Documento de Notificação/Comunicação prévia na Anvisa não preenchido: Número de Notificação/Comunicação prévia na Anvisa não preenchido
A11: Não verificado | B11: Alto | C11: MLB1349521867 | D11: =HYPERLINK("https://www.mercadolivre.com.br/anuncios?page=1&sort=DEFAULT&search="&C11,"Abrir anúncio ↗") -> Abrir anúncio ↗ | E11: Perfume Natural De Mirra - Feminino Natural 100ml | F11: Inativo | G11: Código universal do produto (GTIN) não preenchido (texto de exemplo do ML ainda lá); Descrição repetida em outros anúncios com título diferente (verificar se é boilerplate ou erro); Documento de Notificação/Comunicação prévia na Anvisa não preenchido; Gênero cadastrado diverge do gênero indicado no título | H11: Descrição repetida em outros anúncios com título diferente (verificar se é boilerplate ou erro): Mesma descrição usada em 27 anúncios com títulos diferentes | Código universal do produto (GTIN) não preenchido (texto de exemplo do ML ainda lá): Texto de exemplo do template não foi substituído pelo código real | Documento de Notificação/Comunicação prévia na Anvisa não preenchido: Número de Notificação/Comunicação prévia na Anvisa não preenchido | Gênero cadastrado diverge do gênero indicado no título: Título indica um gênero mas campo Gênero está "Masculino" - risco do cliente comprar errado
A12: Não verificado | B12: Alto | C12: MLB1349521870 | D12: =HYPERLINK("https://www.mercadolivre.com.br/anuncios?page=1&sort=DEFAULT&search="&C12,"Abrir anúncio ↗") -> Abrir anúncio ↗ | E12: Perfume Masculino Natural Gengibre 100ml | F12: Ativo | G12: Descrição repetida em outros anúncios com título diferente (verificar se é boilerplate ou erro); Documento de Notificação/Comunicação prévia na Anvisa não preenchido | H12: Descrição repetida em outros anúncios com título diferente (verificar se é boilerplate ou erro): Mesma descrição usada em 27 anúncios com títulos diferentes | Documento de Notificação/Comunicação prévia na Anvisa não preenchido: Número de Notificação/Comunicação prévia na Anvisa não preenchido
A13: Não verificado | B13: Alto | C13: MLB1349521882 | D13: =HYPERLINK("https://www.mercadolivre.com.br/anuncios?page=1&sort=DEFAULT&search="&C13,"Abrir anúncio ↗") -> Abrir anúncio ↗ | E13: Perfume Masculino Natural Eucalipto 100ml | F13: Ativo | G13: Ano de lançamento preenchido (deveria ficar em branco); Descrição repetida em outros anúncios com título diferente (verificar se é boilerplate ou erro); Documento de Notificação/Comunicação prévia na Anvisa não preenchido | H13: Descrição repetida em outros anúncios com título diferente (verificar se é boilerplate ou erro): Mesma descrição usada em 27 anúncios com títulos diferentes | Ano de lançamento preenchido (deveria ficar em branco): Ano de lançamento preenchido ("1996") - regra do negócio é deixar em branco | Documento de Notificação/Comunicação prévia na Anvisa não preenchido: Número de Notificação/Comunicação prévia na Anvisa não preenchido
... A3139: Não verificado | B3139: Médio | C3139: MLB7294020562 | D3139: =HYPERLINK("https://www.mercadolivre.com.br/anuncios?page=1&sort=DEFAULT&search="&C3139,"Abrir anúncio ↗") -> Abrir anúncio ↗ | E3139: Perfume Saudável Feminino Notas De Alecrim 100ml - Natural | F3139: Inativo | G3139: Documento de Notificação/Comunicação prévia na Anvisa não preenchido | H3139: Documento de Notificação/Comunicação prévia na Anvisa não preenchido: Número de Notificação/Comunicação prévia na Anvisa não preenchido

Sheet 💧 Óleos Essenciais
A1: Status | B1: Gravidade | C1: Código do Anúncio | D1: Link | E1: Título Atual | F1: Situação no ML | G1: Problema(s) Encontrado(s) | H1: Detalhes / Sugestão de Correção | I1: Responsável | J1: Data | K1: Observações
A2: Não verificado | B2: Crítico | C2: MLB1857908107 | D2: =HYPERLINK("https://www.mercadolivre.com.br/anuncios?page=1&sort=DEFAULT&search="&C2,"Abrir anúncio ↗") -> Abrir anúncio ↗ | E2: Óleo Essencial De Lemongrass 10ml - Puro E Natural - Oferta | F2: Ativo | G2: Documento de Notificação/Comunicação prévia na Anvisa não preenchido; Óleo essencial 100% puro marcado como adequado para massagem (risco ao cliente) | H2: Óleo essencial 100% puro marcado como adequado para massagem (risco ao cliente): Óleo essencial 100% puro (sem óleo vegetal/carreador) marcado como adequado para massagens - risco de uso incorreto/queimadura pelo cliente | Documento de Notificação/Comunicação prévia na Anvisa não preenchido: Número de Notificação/Comunicação prévia na Anvisa não preenchido
A3: Não verificado | B3: Crítico | C3: MLB1857949829 | D3: =HYPERLINK("https://www.mercadolivre.com.br/anuncios?page=1&sort=DEFAULT&search="&C3,"Abrir anúncio ↗") -> Abrir anúncio ↗ | E3: Kit 6 Óleos Essenciais 10ml - Puro E Natural | F3: Ativo | G3: Documento de Notificação/Comunicação prévia na Anvisa não preenchido; Óleo essencial 100% puro marcado como adequado para massagem (risco ao cliente) | H3: Óleo essencial 100% puro marcado como adequado para massagem (risco ao cliente): Óleo essencial 100% puro (sem óleo vegetal/carreador) marcado como adequado para massagens - risco de uso incorreto/queimadura pelo cliente | Documento de Notificação/Comunicação prévia na Anvisa não preenchido: Número de Notificação/Comunicação prévia na Anvisa não preenchido
A4: Não verificado | B4: Crítico | C4: MLB1872203615 | D4: =HYPERLINK("https://www.mercadolivre.com.br/anuncios?page=1&sort=DEFAULT&search="&C4,"Abrir anúncio ↗") -> Abrir anúncio ↗ | E4: Óleo Essencial Erva Cidreira 10ml - Puro E Natural - Oferta | F4: Ativo | G4: Documento de Notificação/Comunicação prévia na Anvisa não preenchido; Óleo essencial 100% puro marcado como adequado para massagem (risco ao cliente) | H4: Óleo essencial 100% puro marcado como adequado para massagem (risco ao cliente): Óleo essencial 100% puro (sem óleo vegetal/carreador) marcado como adequado para massagens - risco de uso incorreto/queimadura pelo cliente | Documento de Notificação/Comunicação prévia na Anvisa não preenchido: Número de Notificação/Comunicação prévia na Anvisa não preenchido
A5: Não verificado | B5: Crítico | C5: MLB1874306660 | D5: =HYPERLINK("https://www.mercadolivre.com.br/anuncios?page=1&sort=DEFAULT&search="&C5,"Abrir anúncio ↗") -> Abrir anúncio ↗ | E5: Óleo Essencial Ylang Ylang 10 Ml - Puro E Natural | F5: Ativo | G5: Documento de Notificação/Comunicação prévia na Anvisa não preenchido; Óleo essencial 100% puro marcado como adequado para massagem (risco ao cliente) | H5: Óleo essencial 100% puro marcado como adequado para massagem (risco ao cliente): Óleo essencial 100% puro (sem óleo vegetal/carreador) marcado como adequado para massagens - risco de uso incorreto/queimadura pelo cliente | Documento de Notificação/Comunicação prévia na Anvisa não preenchido: Número de Notificação/Comunicação prévia na Anvisa não preenchido
A6: Não verificado | B6: Crítico | C6: MLB1874312989 | D6: =HYPERLINK("https://www.mercadolivre.com.br/anuncios?page=1&sort=DEFAULT&search="&C6,"Abrir anúncio ↗") -> Abrir anúncio ↗ | E6: Óleo Essencial Hortelã Pimenta 10 Ml - Puro E Natural | F6: Ativo | G6: Documento de Notificação/Comunicação prévia na Anvisa não preenchido; Óleo essencial 100% puro marcado como adequado para massagem (risco ao cliente) | H6: Óleo essencial 100% puro marcado como adequado para massagem (risco ao cliente): Óleo essencial 100% puro (sem óleo vegetal/carreador) marcado como adequado para massagens - risco de uso incorreto/queimadura pelo cliente | Documento de Notificação/Comunicação prévia na Anvisa não preenchido: Número de Notificação/Comunicação prévia na Anvisa não preenchido
A7: Não verificado | B7: Crítico | C7: MLB1959749529 | D7: =HYPERLINK("https://www.mercadolivre.com.br/anuncios?page=1&sort=DEFAULT&search="&C7,"Abrir anúncio ↗") -> Abrir anúncio ↗ | E7: Kit 2 Óleos Essenciais 10ml - Lemongrass + Anis Estrelado | F7: Ativo | G7: Código universal do produto (GTIN) não preenchido (texto de exemplo do ML ainda lá); Documento de Notificação/Comunicação prévia na Anvisa não preenchido; Óleo essencial 100% puro marcado como adequado para massagem (risco ao cliente) | H7: Código universal do produto (GTIN) não preenchido (texto de exemplo do ML ainda lá): Texto de exemplo do template não foi substituído pelo código real | Óleo essencial 100% puro marcado como adequado para massagem (risco ao cliente): Óleo essencial 100% puro (sem óleo vegetal/carreador) marcado como adequado para massagens - risco de uso incorreto/queimadura pelo cliente | Documento de Notificação/Comunicação prévia na Anvisa não preenchido: Número de Notificação/Comunicação prévia na Anvisa não preenchido
A8: Não verificado | B8: Crítico | C8: MLB1959749539 | D8: =HYPERLINK("https://www.mercadolivre.com.br/anuncios?page=1&sort=DEFAULT&search="&C8,"Abrir anúncio ↗") -> Abrir anúncio ↗ | E8: Kit 2 Óleos Essenciais - 2 Alecrim 10ml | F8: Ativo | G8: Documento de Notificação/Comunicação prévia na Anvisa não preenchido; Óleo essencial 100% puro marcado como adequado para massagem (risco ao cliente) | H8: Óleo essencial 100% puro marcado como adequado para massagem (risco ao cliente): Óleo essencial 100% puro (sem óleo vegetal/carreador) marcado como adequado para massagens - risco de uso incorreto/queimadura pelo cliente | Documento de Notificação/Comunicação prévia na Anvisa não preenchido: Número de Notificação/Comunicação prévia na Anvisa não preenchido
A9: Não verificado | B9: Crítico | C9: MLB1959755622 | D9: =HYPERLINK("https://www.mercadolivre.com.br/anuncios?page=1&sort=DEFAULT&search="&C9,"Abrir anúncio ↗") -> Abrir anúncio ↗ | E9: Kit 2 Óleos Essenciais - 2 Eucalipto (lima Limão) 10ml | F9: Ativo | G9: Documento de Notificação/Comunicação prévia na Anvisa não preenchido; Óleo essencial 100% puro marcado como adequado para massagem (risco ao cliente) | H9: Óleo essencial 100% puro marcado como adequado para massagem (risco ao cliente): Óleo essencial 100% puro (sem óleo vegetal/carreador) marcado como adequado para massagens - risco de uso incorreto/queimadura pelo cliente | Documento de Notificação/Comunicação prévia na Anvisa não preenchido: Número de Notificação/Comunicação prévia na Anvisa não preenchido
A10: Não verificado | B10: Crítico | C10: MLB1959766656 | D10: =HYPERLINK("https://www.mercadolivre.com.br/anuncios?page=1&sort=DEFAULT&search="&C10,"Abrir anúncio ↗") -> Abrir anúncio ↗ | E10: Kit 2 Óleos Essenciais - 2 Melaleuca 10ml | F10: Ativo | G10: Código universal do produto (GTIN) não preenchido (texto de exemplo do ML ainda lá); Documento de Notificação/Comunicação prévia na Anvisa não preenchido; Óleo essencial 100% puro marcado como adequado para massagem (risco ao cliente) | H10: Código universal do produto (GTIN) não preenchido (texto de exemplo do ML ainda lá): Texto de exemplo do template não foi substituído pelo código real | Óleo essencial 100% puro marcado como adequado para massagem (risco ao cliente): Óleo essencial 100% puro (sem óleo vegetal/carreador) marcado como adequado para massagens - risco de uso incorreto/queimadura pelo cliente | Documento de Notificação/Comunicação prévia na Anvisa não preenchido: Número de Notificação/Comunicação prévia na Anvisa não preenchido
A11: Não verificado | B11: Crítico | C11: MLB1959766667 | D11: =HYPERLINK("https://www.mercadolivre.com.br/anuncios?page=1&sort=DEFAULT&search="&C11,"Abrir anúncio ↗") -> Abrir anúncio ↗ | E11: Kit 2 Óleos Essenciais 10ml - Melaleuca + Citronela | F11: Ativo | G11: Documento de Notificação/Comunicação prévia na Anvisa não preenchido; Óleo essencial 100% puro marcado como adequado para massagem (risco ao cliente) | H11: Óleo essencial 100% puro marcado como adequado para massagem (risco ao cliente): Óleo essencial 100% puro (sem óleo vegetal/carreador) marcado como adequado para massagens - risco de uso incorreto/queimadura pelo cliente | Documento de Notificação/Comunicação prévia na Anvisa não preenchido: Número de Notificação/Comunicação prévia na Anvisa não preenchido
A12: Não verificado | B12: Crítico | C12: MLB1959766813 | D12: =HYPERLINK("https://www.mercadolivre.com.br/anuncios?page=1&sort=DEFAULT&search="&C12,"Abrir anúncio ↗") -> Abrir anúncio ↗ | E12: Kit 2 Óleos Essenciais 10ml - Alecrim + Limão Siciliano | F12: Ativo | G12: Documento de Notificação/Comunicação prévia na Anvisa não preenchido; Óleo essencial 100% puro marcado como adequado para massagem (risco ao cliente) | H12: Óleo essencial 100% puro marcado como adequado para massagem (risco ao cliente): Óleo essencial 100% puro (sem óleo vegetal/carreador) marcado como adequado para massagens - risco de uso incorreto/queimadura pelo cliente | Documento de Notificação/Comunicação prévia na Anvisa não preenchido: Número de Notificação/Comunicação prévia na Anvisa não preenchido
A13: Não verificado | B13: Crítico | C13: MLB1960337097 | D13: =HYPERLINK("https://www.mercadolivre.com.br/anuncios?page=1&sort=DEFAULT&search="&C13,"Abrir anúncio ↗") -> Abrir anúncio ↗ | E13: Kit 2 Óleos Essenciais 10ml - Laranja Amarga + Laranja Doce | F13: Ativo | G13: Documento de Notificação/Comunicação prévia na Anvisa não preenchido; Óleo essencial 100% puro marcado como adequado para massagem (risco ao cliente) | H13: Óleo essencial 100% puro marcado como adequado para massagem (risco ao cliente): Óleo essencial 100% puro (sem óleo vegetal/carreador) marcado como adequado para massagens - risco de uso incorreto/queimadura pelo cliente | Documento de Notificação/Comunicação prévia na Anvisa não preenchido: Número de Notificação/Comunicação prévia na Anvisa não preenchido
... A1533: Não verificado | B1533: Médio | C1533: MLB7294020554 | D1533: =HYPERLINK("https://www.mercadolivre.com.br/anuncios?page=1&sort=DEFAULT&search="&C1533,"Abrir anúncio ↗") -> Abrir anúncio ↗ | E1533: Kit 2 Óleos Essenciais Hortelã Pimenta Roll On 10ml - Puro | F1533: Inativo | G1533: Documento de Notificação/Comunicação prévia na Anvisa não preenchido | H1533: Documento de Notificação/Comunicação prévia na Anvisa não preenchido: Número de Notificação/Comunicação prévia na Anvisa não preenchido

Sheet 📿 Colares
A1: Status | B1: Gravidade | C1: Código do Anúncio | D1: Link | E1: Título Atual | F1: Situação no ML | G1: Problema(s) Encontrado(s) | H1: Detalhes / Sugestão de Correção | I1: Responsável | J1: Data | K1: Observações
A2: Não verificado | B2: Crítico | C2: MLB3259717695 | D2: =HYPERLINK("https://www.mercadolivre.com.br/anuncios?page=1&sort=DEFAULT&search="&C2,"Abrir anúncio ↗") -> Abrir anúncio ↗ | E2: Colar Prata 925 Larimar Bruto Legítimo - Ponte Vecchio Joias | F2: Ativo | G2: Anúncio sem preço definido | H2: Anúncio sem preço definido: Sem preço definido
A3: Não verificado | B3: Alto | C3: MLB2607133402 | D3: =HYPERLINK("https://www.mercadolivre.com.br/anuncios?page=1&sort=DEFAULT&search="&C3,"Abrir anúncio ↗") -> Abrir anúncio ↗ | E3: Colar Em Prata D Lei 925 Pedra Da Lua + Perfume Jasmine 30ml | F3: Inativo | G3: Marca cadastrada incorreta/inconsistente | H3: Marca cadastrada incorreta/inconsistente: Marca "Ponte Vecchio" difere da marca própria esperada "Ponte Vecchio Joias"
A4: Não verificado | B4: Alto | C4: MLB2624168942 | D4: =HYPERLINK("https://www.mercadolivre.com.br/anuncios?page=1&sort=DEFAULT&search="&C4,"Abrir anúncio ↗") -> Abrir anúncio ↗ | E4: Colar Em Prata Banhado Ouro - Veneziano 50cm Trevo Cravejado | F4: Inativo | G4: Marca cadastrada incorreta/inconsistente | H4: Marca cadastrada incorreta/inconsistente: Marca "Ponte Vecchio" difere da marca própria esperada "Ponte Vecchio Joias"
A5: Não verificado | B5: Alto | C5: MLB2624174758 | D5: =HYPERLINK("https://www.mercadolivre.com.br/anuncios?page=1&sort=DEFAULT&search="&C5,"Abrir anúncio ↗") -> Abrir anúncio ↗ | E5: Colar Em Prata 925 Com Banho Em Ouro- Elo Corda 50cm Premium | F5: Inativo | G5: Marca cadastrada incorreta/inconsistente | H5: Marca cadastrada incorreta/inconsistente: Marca "Ponte Vecchio" difere da marca própria esperada "Ponte Vecchio Joias"
A6: Não verificado | B6: Alto | C6: MLB2624174767 | D6: =HYPERLINK("https://www.mercadolivre.com.br/anuncios?page=1&sort=DEFAULT&search="&C6,"Abrir anúncio ↗") -> Abrir anúncio ↗ | E6: Colar Em Prata 925 Elo Veneziano Ponto De Luz Quadrado 7mm | F6: Inativo | G6: Marca cadastrada incorreta/inconsistente | H6: Marca cadastrada incorreta/inconsistente: Marca "Ponte Vecchio" difere da marca própria esperada "Ponte Vecchio Joias"
A7: Não verificado | B7: Alto | C7: MLB2624181226 | D7: =HYPERLINK("https://www.mercadolivre.com.br/anuncios?page=1&sort=DEFAULT&search="&C7,"Abrir anúncio ↗") -> Abrir anúncio ↗ | E7: Colar Em Prata Banhado Ouro Veneziano 45cm Ponto De Luz 6mm | F7: Inativo | G7: Descrição repetida em outros anúncios com título diferente (verificar se é boilerplate ou erro); Marca cadastrada incorreta/inconsistente | H7: Descrição repetida em outros anúncios com título diferente (verificar se é boilerplate ou erro): Mesma descrição usada em 2 anúncios com títulos diferentes | Marca cadastrada incorreta/inconsistente: Marca "Ponte Vecchio" difere da marca própria esperada "Ponte Vecchio Joias"
A8: Não verificado | B8: Alto | C8: MLB2624181239 | D8: =HYPERLINK("https://www.mercadolivre.com.br/anuncios?page=1&sort=DEFAULT&search="&C8,"Abrir anúncio ↗") -> Abrir anúncio ↗ | E8: Colar Banhado Em Ouro Elo Veneziano 50cm Ponto De Luz 5mm | F8: Inativo | G8: Marca cadastrada incorreta/inconsistente | H8: Marca cadastrada incorreta/inconsistente: Marca "Ponte Vecchio" difere da marca própria esperada "Ponte Vecchio Joias"
A9: Não verificado | B9: Alto | C9: MLB2624181240 | D9: =HYPERLINK("https://www.mercadolivre.com.br/anuncios?page=1&sort=DEFAULT&search="&C9,"Abrir anúncio ↗") -> Abrir anúncio ↗ | E9: Colar Em Prata 925 Elo Veneziano Ponto De Luz Coração 5mm | F9: Inativo | G9: Marca cadastrada incorreta/inconsistente | H9: Marca cadastrada incorreta/inconsistente: Marca "Ponte Vecchio" difere da marca própria esperada "Ponte Vecchio Joias"
A10: Não verificado | B10: Alto | C10: MLB2624187577 | D10: =HYPERLINK("https://www.mercadolivre.com.br/anuncios?page=1&sort=DEFAULT&search="&C10,"Abrir anúncio ↗") -> Abrir anúncio ↗ | E10: Colar Em Prata Banhado Ouro Veneziano 45cm Ponto De Luz 5mm | F10: Inativo | G10: Descrição repetida em outros anúncios com título diferente (verificar se é boilerplate ou erro); Marca cadastrada incorreta/inconsistente | H10: Descrição repetida em outros anúncios com título diferente (verificar se é boilerplate ou erro): Mesma descrição usada em 2 anúncios com títulos diferentes | Marca cadastrada incorreta/inconsistente: Marca "Ponte Vecchio" difere da marca própria esperada "Ponte Vecchio Joias"
A11: Não verificado | B11: Alto | C11: MLB2624187578 | D11: =HYPERLINK("https://www.mercadolivre.com.br/anuncios?page=1&sort=DEFAULT&search="&C11,"Abrir anúncio ↗") -> Abrir anúncio ↗ | E11: Colar Em Prata Banhado Ouro Veneziano 50cm Ponto De Luz 6mm | F11: Inativo | G11: Descrição repetida em outros anúncios com título diferente (verificar se é boilerplate ou erro); Marca cadastrada incorreta/inconsistente | H11: Descrição repetida em outros anúncios com título diferente (verificar se é boilerplate ou erro): Mesma descrição usada em 2 anúncios com títulos diferentes | Marca cadastrada incorreta/inconsistente: Marca "Ponte Vecchio" difere da marca própria esperada "Ponte Vecchio Joias"
A12: Não verificado | B12: Alto | C12: MLB2624187580 | D12: =HYPERLINK("https://www.mercadolivre.com.br/anuncios?page=1&sort=DEFAULT&search="&C12,"Abrir anúncio ↗") -> Abrir anúncio ↗ | E12: Colar Banhado Em Ouro Elo Veneziano 50cm Coração Pequeno | F12: Inativo | G12: Marca cadastrada incorreta/inconsistente | H12: Marca cadastrada incorreta/inconsistente: Marca "Ponte Vecchio" difere da marca própria esperada "Ponte Vecchio Joias"
A13: Não verificado | B13: Alto | C13: MLB2624187597 | D13: =HYPERLINK("https://www.mercadolivre.com.br/anuncios?page=1&sort=DEFAULT&search="&C13,"Abrir anúncio ↗") -> Abrir anúncio ↗ | E13: Colar Banhado Em Ouro Elo Veneziano 50cm Ponto De Luz 6mm | F13: Inativo | G13: Marca cadastrada incorreta/inconsistente | H13: Marca cadastrada incorreta/inconsistente: Marca "Ponte Vecchio" difere da marca própria esperada "Ponte Vecchio Joias"
... A425: Não verificado | B425: Alto | C425: MLB7079084360 | D425: =HYPERLINK("https://www.mercadolivre.com.br/anuncios?page=1&sort=DEFAULT&search="&C425,"Abrir anúncio ↗") -> Abrir anúncio ↗ | E425: Colar Prata 925 Singapura Malaquita Polida - Ponte Vecchio Verde | F425: Ativo | G425: Título com mais de 60 caracteres | H425: Título com mais de 60 caracteres: Título com 64 caracteres (limite ML=60)

Sheet 🔶 Pingentes
A1: Status | B1: Gravidade | C1: Código do Anúncio | D1: Link | E1: Título Atual | F1: Situação no ML | G1: Problema(s) Encontrado(s) | H1: Detalhes / Sugestão de Correção | I1: Responsável | J1: Data | K1: Observações
A2: Não verificado | B2: Crítico | C2: MLB4834813528 | D2: =HYPERLINK("https://www.mercadolivre.com.br/anuncios?page=1&sort=DEFAULT&search="&C2,"Abrir anúncio ↗") -> Abrir anúncio ↗ | E2: Colar Prata 925 Singapura Hematita Cruz - P. Vecchio Joias | F2: Inativo | G2: Anúncio sem preço definido; Descrição repetida em outros anúncios com título diferente (verificar se é boilerplate ou erro) | H2: Anúncio sem preço definido: Sem preço definido | Descrição repetida em outros anúncios com título diferente (verificar se é boilerplate ou erro): Mesma descrição usada em 3 anúncios com títulos diferentes
A3: Não verificado | B3: Alto | C3: MLB2624168954 | D3: =HYPERLINK("https://www.mercadolivre.com.br/anuncios?page=1&sort=DEFAULT&search="&C3,"Abrir anúncio ↗") -> Abrir anúncio ↗ | E3: Colar Em Prata Banhado Ouro Elo Veneziano 45cm Nossa Senhora | F3: Inativo | G3: Marca cadastrada incorreta/inconsistente | H3: Marca cadastrada incorreta/inconsistente: Marca "Ponte Vecchio" difere da marca própria esperada "Ponte Vecchio Joias"
A4: Não verificado | B4: Alto | C4: MLB2624187595 | D4: =HYPERLINK("https://www.mercadolivre.com.br/anuncios?page=1&sort=DEFAULT&search="&C4,"Abrir anúncio ↗") -> Abrir anúncio ↗ | E4: Colar Em Prata 925 Elo Veneziano Ponto De Luz Estrela 7mm | F4: Inativo | G4: Marca cadastrada incorreta/inconsistente | H4: Marca cadastrada incorreta/inconsistente: Marca "Ponte Vecchio" difere da marca própria esperada "Ponte Vecchio Joias"
A5: Não verificado | B5: Alto | C5: MLB2624211586 | D5: =HYPERLINK("https://www.mercadolivre.com.br/anuncios?page=1&sort=DEFAULT&search="&C5,"Abrir anúncio ↗") -> Abrir anúncio ↗ | E5: Colar Em Prata Banhado Ouro 18k - 45cm Coração Pequeno | F5: Inativo | G5: Descrição repetida em outros anúncios com título diferente (verificar se é boilerplate ou erro); Marca cadastrada incorreta/inconsistente | H5: Descrição repetida em outros anúncios com título diferente (verificar se é boilerplate ou erro): Mesma descrição usada em 2 anúncios com títulos diferentes | Marca cadastrada incorreta/inconsistente: Marca "Ponte Vecchio" difere da marca própria esperada "Ponte Vecchio Joias"
A6: Não verificado | B6: Alto | C6: MLB2639709004 | D6: =HYPERLINK("https://www.mercadolivre.com.br/anuncios?page=1&sort=DEFAULT&search="&C6,"Abrir anúncio ↗") -> Abrir anúncio ↗ | E6: Colar Em Prata + Ouro Elo Veneziano 45cm Ágata Redonda | F6: Inativo | G6: Marca cadastrada incorreta/inconsistente | H6: Marca cadastrada incorreta/inconsistente: Marca "Ponte Vecchio" difere da marca própria esperada "Ponte Vecchio Joias"
A7: Não verificado | B7: Alto | C7: MLB2639727199 | D7: =HYPERLINK("https://www.mercadolivre.com.br/anuncios?page=1&sort=DEFAULT&search="&C7,"Abrir anúncio ↗") -> Abrir anúncio ↗ | E7: Colar Em Prata + Ouro Elo Veneziano 45cm Olho De Tigre | F7: Inativo | G7: Marca cadastrada incorreta/inconsistente | H7: Marca cadastrada incorreta/inconsistente: Marca "Ponte Vecchio" difere da marca própria esperada "Ponte Vecchio Joias"
A8: Não verificado | B8: Alto | C8: MLB2639727212 | D8: =HYPERLINK("https://www.mercadolivre.com.br/anuncios?page=1&sort=DEFAULT&search="&C8,"Abrir anúncio ↗") -> Abrir anúncio ↗ | E8: Colar Em Prata + Ouro Elo Veneziano 45cm Quartzo Verde | F8: Inativo | G8: Marca cadastrada incorreta/inconsistente | H8: Marca cadastrada incorreta/inconsistente: Marca "Ponte Vecchio" difere da marca própria esperada "Ponte Vecchio Joias"
A9: Não verificado | B9: Alto | C9: MLB2650799843 | D9: =HYPERLINK("https://www.mercadolivre.com.br/anuncios?page=1&sort=DEFAULT&search="&C9,"Abrir anúncio ↗") -> Abrir anúncio ↗ | E9: Kit Luxo Perfume Dama Da Noite + Colar Prata 925 E Esmeralda | F9: Ativo | G9: Marca cadastrada incorreta/inconsistente | H9: Marca cadastrada incorreta/inconsistente: Marca "Ponte Vecchio" difere da marca própria esperada "Ponte Vecchio Joias"
A10: Não verificado | B10: Alto | C10: MLB2650825516 | D10: =HYPERLINK("https://www.mercadolivre.com.br/anuncios?page=1&sort=DEFAULT&search="&C10,"Abrir anúncio ↗") -> Abrir anúncio ↗ | E10: Kit Luxo Perfume Dama Da Noite + Colar Prata 925 E Esmeralda | F10: Inativo | G10: Marca cadastrada incorreta/inconsistente | H10: Marca cadastrada incorreta/inconsistente: Marca "Ponte Vecchio" difere da marca própria esperada "Ponte Vecchio Joias"
A11: Não verificado | B11: Alto | C11: MLB2650852077 | D11: =HYPERLINK("https://www.mercadolivre.com.br/anuncios?page=1&sort=DEFAULT&search="&C11,"Abrir anúncio ↗") -> Abrir anúncio ↗ | E11: Colar Prata 925 Esmeralda Polida Natural - P Vecchio Joias | F11: Ativo | G11: Descrição repetida em outros anúncios com título diferente (verificar se é boilerplate ou erro) | H11: Descrição repetida em outros anúncios com título diferente (verificar se é boilerplate ou erro): Mesma descrição usada em 2 anúncios com títulos diferentes
A12: Não verificado | B12: Alto | C12: MLB2658353974 | D12: =HYPERLINK("https://www.mercadolivre.com.br/anuncios?page=1&sort=DEFAULT&search="&C12,"Abrir anúncio ↗") -> Abrir anúncio ↗ | E12: Colar Banhado Ouro 18 Elo Veneziano Zirconia Verde Esmeralda | F12: Inativo | G12: Marca cadastrada incorreta/inconsistente | H12: Marca cadastrada incorreta/inconsistente: Marca "Ponte Vecchio" difere da marca própria esperada "Ponte Vecchio Joias"
A13: Não verificado | B13: Alto | C13: MLB2680910115 | D13: =HYPERLINK("https://www.mercadolivre.com.br/anuncios?page=1&sort=DEFAULT&search="&C13,"Abrir anúncio ↗") -> Abrir anúncio ↗ | E13: Colar Prata 925 Banhada Em Ouro 18k - Pingente Borboleta | F13: Inativo | G13: Marca cadastrada incorreta/inconsistente | H13: Marca cadastrada incorreta/inconsistente: Marca "Ponte Vecchio" difere da marca própria esperada "Ponte Vecchio Joias"
... A501: Não verificado | B501: Alto | C501: MLB7294395368 | D501: =HYPERLINK("https://www.mercadolivre.com.br/anuncios?page=1&sort=DEFAULT&search="&C501,"Abrir anúncio ↗") -> Abrir anúncio ↗ | E501: Pingente Prata 925 Serpentinita Laranja - Natural E Legítima Dourado | F501: Ativo | G501: Anúncio sem descrição; Título com mais de 60 caracteres | H501: Título com mais de 60 caracteres: Título com 68 caracteres (limite ML=60) | Anúncio sem descrição: Descrição vazia

Sheet 💍 Joias e Acessórios
A1: Status | B1: Gravidade | C1: Código do Anúncio | D1: Link | E1: Título Atual | F1: Situação no ML | G1: Problema(s) Encontrado(s) | H1: Detalhes / Sugestão de Correção | I1: Responsável | J1: Data | K1: Observações
A2: Não verificado | B2: Crítico | C2: MLB4628686515 | D2: =HYPERLINK("https://www.mercadolivre.com.br/anuncios?page=1&sort=DEFAULT&search="&C2,"Abrir anúncio ↗") -> Abrir anúncio ↗ | E2: Pulseira De Pedra Natural Granada Verdadeira - P. Vecchio Cor Natural Bordô | F2: Ativo | G2: Anúncio sem descrição; Anúncio sem preço definido; Título com mais de 60 caracteres | H2: Título com mais de 60 caracteres: Título com 75 caracteres (limite ML=60) | Anúncio sem descrição: Descrição vazia | Anúncio sem preço definido: Sem preço definido
A3: Não verificado | B3: Alto | C3: MLB4280447137 | D3: =HYPERLINK("https://www.mercadolivre.com.br/anuncios?page=1&sort=DEFAULT&search="&C3,"Abrir anúncio ↗") -> Abrir anúncio ↗ | E3: Anel Prata 925 Ajustável Granada Oval - Ponte Vecchio Joias | F3: Ativo | G3: Descrição repetida em outros anúncios com título diferente (verificar se é boilerplate ou erro) | H3: Descrição repetida em outros anúncios com título diferente (verificar se é boilerplate ou erro): Mesma descrição usada em 2 anúncios com títulos diferentes
A4: Não verificado | B4: Alto | C4: MLB4280498405 | D4: =HYPERLINK("https://www.mercadolivre.com.br/anuncios?page=1&sort=DEFAULT&search="&C4,"Abrir anúncio ↗") -> Abrir anúncio ↗ | E4: Anel Prata 925 Ajustável Granada Gota - Ponte Vecchio Joias | F4: Ativo | G4: Descrição repetida em outros anúncios com título diferente (verificar se é boilerplate ou erro) | H4: Descrição repetida em outros anúncios com título diferente (verificar se é boilerplate ou erro): Mesma descrição usada em 2 anúncios com títulos diferentes
A5: Não verificado | B5: Alto | C5: MLB4342901561 | D5: =HYPERLINK("https://www.mercadolivre.com.br/anuncios?page=1&sort=DEFAULT&search="&C5,"Abrir anúncio ↗") -> Abrir anúncio ↗ | E5: Anel Ajustável Prata 925 Rubi Natural Ponte Vecchio Joias Prateado | F5: Inativo | G5: Anúncio sem descrição; Título com mais de 60 caracteres | H5: Título com mais de 60 caracteres: Título com 66 caracteres (limite ML=60) | Anúncio sem descrição: Descrição vazia
A6: Não verificado | B6: Alto | C6: MLB6080565628 | D6: =HYPERLINK("https://www.mercadolivre.com.br/anuncios?page=1&sort=DEFAULT&search="&C6,"Abrir anúncio ↗") -> Abrir anúncio ↗ | E6: Anel Banhado Em Ouro 18k Ajustável Ametista E Granada Gota Dourado Ajustável | F6: Inativo | G6: Anúncio sem descrição; Título com mais de 60 caracteres | H6: Título com mais de 60 caracteres: Título com 76 caracteres (limite ML=60) | Anúncio sem descrição: Descrição vazia
A7: Não verificado | B7: Alto | C7: MLB2803522276 | D7: =HYPERLINK("https://www.mercadolivre.com.br/anuncios?page=1&sort=DEFAULT&search="&C7,"Abrir anúncio ↗") -> Abrir anúncio ↗ | E7: Brinco Pérola Em Prata 925 6mm | F7: Inativo | G7: Descrição repetida em outros anúncios com título diferente (verificar se é boilerplate ou erro) | H7: Descrição repetida em outros anúncios com título diferente (verificar se é boilerplate ou erro): Mesma descrição usada em 7 anúncios com títulos diferentes
A8: Não verificado | B8: Alto | C8: MLB2803528007 | D8: =HYPERLINK("https://www.mercadolivre.com.br/anuncios?page=1&sort=DEFAULT&search="&C8,"Abrir anúncio ↗") -> Abrir anúncio ↗ | E8: Brinco Prata 925 Ponto De Luz 4mm | F8: Inativo | G8: Descrição repetida em outros anúncios com título diferente (verificar se é boilerplate ou erro) | H8: Descrição repetida em outros anúncios com título diferente (verificar se é boilerplate ou erro): Mesma descrição usada em 7 anúncios com títulos diferentes
A9: Não verificado | B9: Alto | C9: MLB2803528016 | D9: =HYPERLINK("https://www.mercadolivre.com.br/anuncios?page=1&sort=DEFAULT&search="&C9,"Abrir anúncio ↗") -> Abrir anúncio ↗ | E9: Brinco Prata 925 Ponto De Luz Ametista 3mm | F9: Inativo | G9: Descrição repetida em outros anúncios com título diferente (verificar se é boilerplate ou erro) | H9: Descrição repetida em outros anúncios com título diferente (verificar se é boilerplate ou erro): Mesma descrição usada em 7 anúncios com títulos diferentes
A10: Não verificado | B10: Alto | C10: MLB2803533333 | D10: =HYPERLINK("https://www.mercadolivre.com.br/anuncios?page=1&sort=DEFAULT&search="&C10,"Abrir anúncio ↗") -> Abrir anúncio ↗ | E10: Brinco Prata 925 Ponto De Luz 6mm | F10: Inativo | G10: Descrição repetida em outros anúncios com título diferente (verificar se é boilerplate ou erro) | H10: Descrição repetida em outros anúncios com título diferente (verificar se é boilerplate ou erro): Mesma descrição usada em 7 anúncios com títulos diferentes
A11: Não verificado | B11: Alto | C11: MLB2803551106 | D11: =HYPERLINK("https://www.mercadolivre.com.br/anuncios?page=1&sort=DEFAULT&search="&C11,"Abrir anúncio ↗") -> Abrir anúncio ↗ | E11: Brinco Prata 925 Ponto De Luz Rubi 3mm | F11: Inativo | G11: Descrição repetida em outros anúncios com título diferente (verificar se é boilerplate ou erro) | H11: Descrição repetida em outros anúncios com título diferente (verificar se é boilerplate ou erro): Mesma descrição usada em 7 anúncios com títulos diferentes
A12: Não verificado | B12: Alto | C12: MLB2897258542 | D12: =HYPERLINK("https://www.mercadolivre.com.br/anuncios?page=1&sort=DEFAULT&search="&C12,"Abrir anúncio ↗") -> Abrir anúncio ↗ | E12: Brinco Flor Em Prata 925 E Zircônia - Ponte Vecchio | F12: Inativo | G12: Descrição repetida em outros anúncios com título diferente (verificar se é boilerplate ou erro) | H12: Descrição repetida em outros anúncios com título diferente (verificar se é boilerplate ou erro): Mesma descrição usada em 7 anúncios com títulos diferentes
A13: Não verificado | B13: Alto | C13: MLB3037062909 | D13: =HYPERLINK("https://www.mercadolivre.com.br/anuncios?page=1&sort=DEFAULT&search="&C13,"Abrir anúncio ↗") -> Abrir anúncio ↗ | E13: Brinco Argola Em Prata 925 Liso Elegante Ponte Vecchio Joias | F13: Inativo | G13: Descrição repetida em outros anúncios com título diferente (verificar se é boilerplate ou erro) | H13: Descrição repetida em outros anúncios com título diferente (verificar se é boilerplate ou erro): Mesma descrição usada em 7 anúncios com títulos diferentes
... A36: Não verificado | B36: Médio | C36: MLB4294638485 | D36: =HYPERLINK("https://www.mercadolivre.com.br/anuncios?page=1&sort=DEFAULT&search="&C36,"Abrir anúncio ↗") -> Abrir anúncio ↗ | E36: Brinco Prata 925 Larimar Oval Verdadeiro Natural P. Vecchio | F36: Ativo | G36: Campo Marca em branco | H36: Campo Marca em branco: Marca não preenchida

Sheet 🌬️ Difusores e Aromatizadores
A1: Status | B1: Gravidade | C1: Código do Anúncio | D1: Link | E1: Título Atual | F1: Situação no ML | G1: Problema(s) Encontrado(s) | H1: Detalhes / Sugestão de Correção | I1: Responsável | J1: Data | K1: Observações
A2: Não verificado | B2: Alto | C2: MLB2166250981 | D2: =HYPERLINK("https://www.mercadolivre.com.br/anuncios?page=1&sort=DEFAULT&search="&C2,"Abrir anúncio ↗") -> Abrir anúncio ↗ | E2: Aromatizador De Ambiente Para Hotéis 250ml + Presente | F2: Ativo | G2: Campo Marca em branco; Código universal do produto (GTIN) não preenchido (texto de exemplo do ML ainda lá); Descrição menciona horário/prazo fixo de despacho; Descrição repetida em outros anúncios com título diferente (verificar se é boilerplate ou erro) | H2: Descrição repetida em outros anúncios com título diferente (verificar se é boilerplate ou erro): Mesma descrição usada em 2 anúncios com títulos diferentes | Campo Marca em branco: Marca não preenchida | Campo Marca em branco: Marca não preenchida | Campo Marca em branco: Marca não preenchida | Campo Marca em branco: Marca não preenchida | Campo Marca em branco: Marca não preenchida | Código universal do produto (GTIN) não preenchido (texto de exemplo do ML ainda lá): Texto de exemplo do template não foi substituído pelo código real | Campo Marca em branco: Marca não preenchida | Campo Marca em branco: Marca não preenchida | Campo Marca em branco: Marca não preenchida | Campo Marca em branco: Marca não preenchida | Campo Marca em branco: Marca não preenchida | Descrição menciona horário/prazo fixo de despacho: Descrição menciona horário/prazo de despacho fixo - texto operacional que pode ficar desatualizado
